import math
import sys
import traceback

import discord
from discord.ext import commands


class CommandErrorHandler(commands.Cog):
    """
    Module for handling errors, no need for anyone to use this.
    """

    def __init__(self, bot):
        self.bot = bot

    @commands.Cog.listener()
    async def on_command_error(self, ctx, error):
        """The event triggered when an error is raised while invoking a command.
        Parameters
        ------------
        ctx: commands.Context
        The context used for command invocation.
        error: commands.CommandError
        The Exception raised.
        """
        if hasattr(ctx.command, 'on_error'):
            return

        if isinstance(error, commands.NoPrivateMessage):
            await ctx.author.send('This command cannot be used in private messages.')
        elif isinstance(error, commands.DisabledCommand):
            await ctx.author.send('Sorry. This command is disabled and cannot be used.')
        elif isinstance(error, commands.CommandInvokeError):
            print(f'In {ctx.command.qualified_name}:', file=sys.stderr)
            traceback.print_tb(error.original.__traceback__)
            print(
                f'{error.original.__class__.__name__}: {error.original}', file=sys.stderr)

        cog = ctx.cog
        if cog:
            if cog._get_overridden_method(cog.cog_command_error) is not None:
                return

        ignored = (commands.CommandNotFound,)
        error = getattr(error, 'original', error)

        if isinstance(error, ignored):
            return

        if isinstance(error, commands.DisabledCommand):
            await ctx.send(f'{ctx.command} has been disabled.')

        elif isinstance(error, commands.NoPrivateMessage):
            try:
                await ctx.author.send(f'{ctx.command} can not be used in Private Messages.')
            except discord.HTTPException:
                pass

        elif isinstance(error, commands.BadArgument):
            if ctx.command.qualified_name == 'tag list':
                await ctx.send('I could not find that member. Please try again.')

        else:
            print('Ignoring exception in command {}:'.format(ctx.command), file=sys.stderr)
            traceback.print_exception(type(error), error, error.__traceback__, file=sys.stderr)

        # if command has local error handler, return
        if hasattr(ctx.command, 'on_error'):
            return

        # get the original exception
        error = getattr(error, 'original', error)

        if isinstance(error, commands.CommandNotFound):
            return

        if isinstance(error, commands.BotMissingPermissions):
            missing = [perm.replace('_', ' ').replace('guild', 'server').title() for perm in error.missing_perms]
            if len(missing) > 2:
                fmt = '{}, and {}'.format("**, **".join(missing[:-1]), missing[-1])
            else:
                fmt = ' and '.join(missing)
            _message = 'I need the **{}** permission(s) to run this command.'.format(fmt)
            await ctx.send(_message)
            return

        if isinstance(error, commands.DisabledCommand):
            await ctx.send('This command has been disabled.')
            return

        if isinstance(error, commands.CommandOnCooldown):
            await ctx.send("This command is on cool down, please retry in {}s.".format(math.ceil(error.retry_after)))
            return

        if isinstance(error, commands.MissingPermissions):
            missing = [perm.replace('_', ' ').replace('guild', 'server').title() for perm in error.missing_perms]
            if len(missing) > 2:
                fmt = '{}, and {}'.format("**, **".join(missing[:-1]), missing[-1])
            else:
                fmt = ' and '.join(missing)
            _message = 'You need the **{}** permission(s) to use this command.'.format(fmt)
            await ctx.send(_message)
            return

        if isinstance(error, commands.UserInputError):
            await ctx.send("Invalid input.")
            await self.send_command_help(ctx)
            return

        if isinstance(error, commands.NoPrivateMessage):
            try:
                await ctx.author.send('This command cannot be used in direct messages.')
            except discord.Forbidden:
                pass
            return

        if isinstance(error, commands.CheckFailure):
            await ctx.send("You do not have permission to use this command.")
            return

        # ignore all other exception types, but print them to stderr
        print('Ignoring exception in command {}:'.format(ctx.command), file=sys.stderr)

        traceback.print_exception(type(error), error, error.__traceback__, file=sys.stderr)


def setup(bot):
    bot.add_cog(CommandErrorHandler(bot))
